Traceback (most recent call last):
  File "/home/jebarrios/anaconda3/envs/kwant/lib/python3.6/site-packages/nbclient/client.py", line 626, in _async_poll_for_reply
    msg = await ensure_async(self.kc.shell_channel.get_msg(timeout=new_timeout))
  File "/home/jebarrios/anaconda3/envs/kwant/lib/python3.6/site-packages/nbclient/util.py", line 96, in ensure_async
    result = await obj
  File "/home/jebarrios/anaconda3/envs/kwant/lib/python3.6/site-packages/jupyter_client/channels.py", line 230, in get_msg
    raise Empty
queue.Empty

During handling of the above exception, another exception occurred:

Traceback (most recent call last):
  File "/home/jebarrios/anaconda3/envs/kwant/lib/python3.6/site-packages/jupyter_cache/executors/utils.py", line 56, in single_nb_execution
    record_timing=False,
  File "/home/jebarrios/anaconda3/envs/kwant/lib/python3.6/site-packages/nbclient/client.py", line 1093, in execute
    return NotebookClient(nb=nb, resources=resources, km=km, **kwargs).execute()
  File "/home/jebarrios/anaconda3/envs/kwant/lib/python3.6/site-packages/nbclient/util.py", line 84, in wrapped
    return just_run(coro(*args, **kwargs))
  File "/home/jebarrios/anaconda3/envs/kwant/lib/python3.6/site-packages/nbclient/util.py", line 62, in just_run
    return loop.run_until_complete(coro)
  File "/home/jebarrios/anaconda3/envs/kwant/lib/python3.6/asyncio/base_events.py", line 488, in run_until_complete
    return future.result()
  File "/home/jebarrios/anaconda3/envs/kwant/lib/python3.6/site-packages/nbclient/client.py", line 560, in async_execute
    cell, index, execution_count=self.code_cells_executed + 1
  File "/home/jebarrios/anaconda3/envs/kwant/lib/python3.6/site-packages/nbclient/client.py", line 838, in async_execute_cell
    exec_reply = await self.task_poll_for_reply
  File "/home/jebarrios/anaconda3/envs/kwant/lib/python3.6/site-packages/nbclient/client.py", line 650, in _async_poll_for_reply
    await self._async_handle_timeout(timeout, cell)
  File "/home/jebarrios/anaconda3/envs/kwant/lib/python3.6/site-packages/nbclient/client.py", line 698, in _async_handle_timeout
    "Cell execution timed out", timeout, cell
nbclient.exceptions.CellTimeoutError: A cell timed out while it was being executed, after 30 seconds.
The message was: Cell execution timed out.
Here is a preview of the cell contents:
-------------------

%%time
e=15
Ek1,ψ1,max_u1= Strain(0,2, cos(2*pi*Y/L),0.0) 
Ek2,ψ2,max_u2= Strain(e,2, cos(2*pi*Y/L),0.0) 
Ek3,ψ3,max_u3= Strain(e,2, cos(4*pi*Y/L),0.0) 
Ek4,ψ4,max_u4= Strain(e,2, cos(6*pi*Y/L),0.0) 
Ek5,ψ5,max_u5= Strain(e,2, cos(10*pi*Y/L),0.0) 
Ek6,ψ6,max_u6= Strain(e,2, cos(12*pi*Y/L),0.0) 
-------------------

